{"name": "test_login_fail[case4]", "status": "passed", "attachments": [{"name": "log", "source": "1236f286-ee2c-434f-802a-5ec04acb45c2-attachment.txt", "type": "text/plain"}], "parameters": [{"name": "case", "value": "{'title': '密码错误，登录第四次', 'phone': '17610772806', 'pwd': 'python22', 'expected': '密码错误, 若再次失败, 10分钟内将禁止登入'}"}], "start": 1604474245794, "stop": 1604474246461, "uuid": "b1a0ea61-1031-4304-889b-d2f8c1a80350", "historyId": "3b6f221be821b02d1283e6212a9368bc", "testCaseId": "2a81b10f036ab8a26bb49e6669c3c22b", "fullName": "testcase.test_01login.TestLogin#test_login_fail", "labels": [{"name": "parentSuite", "value": "testcase"}, {"name": "suite", "value": "test_01login"}, {"name": "subSuite", "value": "TestLogin"}, {"name": "host", "value": "ZBMAC-C02WD0XQH.local"}, {"name": "thread", "value": "18542-MainThread"}, {"name": "framework", "value": "pytest"}, {"name": "language", "value": "cpython3"}, {"name": "package", "value": "testcase.test_01login"}]}